[11/12/23 11:44:34] ERROR    Node 'linear_regression_evaluation: evaluate_model([linear_regression_output]) node.py:356
                             -> [linear_regression_evaluation_plot]' failed with error:
                             0.3311942686297829
                    WARNING  There are 2 nodes that have not run.                                         runner.py:217
                             You can resume the pipeline run from the nearest nodes with persisted inputs
                             by adding the following argument to your previous command:
                               --from-nodes "random_forest_evaluation,linear_regression_evaluation"
Traceback (most recent call last):
  File "D:\Program Files\Python\lib\runpy.py", line 196, in _run_module_as_main
    return _run_code(code, main_globals, None,
  File "D:\Program Files\Python\lib\runpy.py", line 86, in _run_code
    exec(code, run_globals)
  File "D:\Program Files\Python\Scripts\kedro.exe\__main__.py", line 7, in <module>
    sys.exit(main())
  File "D:\Program Files\Python\lib\site-packages\kedro\framework\cli\cli.py", line 211, in main
    cli_collection()
  File "D:\Program Files\Python\lib\site-packages\click\core.py", line 1157, in __call__
    return self.main(*args, **kwargs)
  File "D:\Program Files\Python\lib\site-packages\kedro\framework\cli\cli.py", line 139, in main
    super().main(
  File "D:\Program Files\Python\lib\site-packages\click\core.py", line 1078, in main
    rv = self.invoke(ctx)
  File "D:\Program Files\Python\lib\site-packages\click\core.py", line 1688, in invoke
    return _process_result(sub_ctx.command.invoke(sub_ctx))
  File "D:\Program Files\Python\lib\site-packages\click\core.py", line 1434, in invoke
    return ctx.invoke(self.callback, **ctx.params)
  File "D:\Program Files\Python\lib\site-packages\click\core.py", line 783, in invoke
    return __callback(*args, **kwargs)
  File "D:\Program Files\Python\lib\site-packages\kedro\framework\cli\project.py", line 453, in run
    session.run(
  File "D:\Program Files\Python\lib\site-packages\kedro\framework\session\session.py", line 436, in run
    run_result = runner.run(
  File "D:\Program Files\Python\lib\site-packages\kedro\runner\runner.py", line 103, in run
    self._run(pipeline, catalog, hook_manager, session_id)
  File "D:\Program Files\Python\lib\site-packages\kedro\runner\sequential_runner.py", line 70, in _run
    run_node(node, catalog, hook_manager, self._is_async, session_id)
  File "D:\Program Files\Python\lib\site-packages\kedro\runner\runner.py", line 331, in run_node
    node = _run_node_sequential(node, catalog, hook_manager, session_id)
  File "D:\Program Files\Python\lib\site-packages\kedro\runner\runner.py", line 426, in _run_node_sequential
    outputs = _call_node_run(
  File "D:\Program Files\Python\lib\site-packages\kedro\runner\runner.py", line 392, in _call_node_run
    raise exc
  File "D:\Program Files\Python\lib\site-packages\kedro\runner\runner.py", line 382, in _call_node_run
    outputs = node.run(inputs)
  File "D:\Program Files\Python\lib\site-packages\kedro\pipeline\node.py", line 357, in run
    raise exc
  File "D:\Program Files\Python\lib\site-packages\kedro\pipeline\node.py", line 346, in run
    outputs = self._run_with_one_input(inputs, self._inputs)
  File "D:\Program Files\Python\lib\site-packages\kedro\pipeline\node.py", line 377, in _run_with_one_input
    return self._func(inputs[node_input])
  File "C:\Users\Administrator\Desktop\PJATK\Semestr_VII\ASI\ASI_Group\asi-kedro\src\asi_kedro\pipelines\model_evaluation\nodes.py", line 59, in evaluate_model
    axes = prediction_summary(predictions_test['y_true'].values, predictions_test['y_pred'].values, "Random Forest")
  File "C:\Users\Administrator\Desktop\PJATK\Semestr_VII\ASI\ASI_Group\asi-kedro\src\asi_kedro\pipelines\model_evaluation\nodes.py", line 46, in prediction_summary
    wandb.log({"confusion_matrix": wandb.plot.confusion_matrix(probs=None,
  File "D:\Program Files\Python\lib\site-packages\wandb\plot\confusion_matrix.py", line 78, in confusion_matrix
    counts[class_mapping[y_true[i]], class_mapping[preds[i]]] += 1
KeyError: 0.3311942686297829
┌─────────────────────────────── Traceback (most recent call last) ────────────────────────────────┐
│ D:\Program Files\Python\lib\runpy.py:196 in _run_module_as_main                                  │
│                                                                                                  │
│ D:\Program Files\Python\lib\runpy.py:86 in _run_code                                             │
│                                                                                                  │
│ in <module>:7                                                                                    │
│                                                                                                  │
│ D:\Program Files\Python\lib\site-packages\kedro\framework\cli\cli.py:211 in main                 │
│                                                                                                  │
│ D:\Program Files\Python\lib\site-packages\click\core.py:1157 in __call__                         │
│                                                                                                  │
│ D:\Program Files\Python\lib\site-packages\kedro\framework\cli\cli.py:139 in main                 │
│                                                                                                  │
│ D:\Program Files\Python\lib\site-packages\click\core.py:1078 in main                             │
│                                                                                                  │
│ D:\Program Files\Python\lib\site-packages\click\core.py:1688 in invoke                           │
│                                                                                                  │
│ D:\Program Files\Python\lib\site-packages\click\core.py:1434 in invoke                           │
│                                                                                                  │
│ D:\Program Files\Python\lib\site-packages\click\core.py:783 in invoke                            │
│                                                                                                  │
│ D:\Program Files\Python\lib\site-packages\kedro\framework\cli\project.py:453 in run              │
│                                                                                                  │
│ D:\Program Files\Python\lib\site-packages\kedro\framework\session\session.py:436 in run          │
│                                                                                                  │
│ D:\Program Files\Python\lib\site-packages\kedro\runner\runner.py:103 in run                      │
│                                                                                                  │
│ D:\Program Files\Python\lib\site-packages\kedro\runner\sequential_runner.py:70 in _run           │
│                                                                                                  │
│ D:\Program Files\Python\lib\site-packages\kedro\runner\runner.py:331 in run_node                 │
│                                                                                                  │
│ D:\Program Files\Python\lib\site-packages\kedro\runner\runner.py:426 in _run_node_sequential     │
│                                                                                                  │
│ D:\Program Files\Python\lib\site-packages\kedro\runner\runner.py:392 in _call_node_run           │
│                                                                                                  │
│ D:\Program Files\Python\lib\site-packages\kedro\runner\runner.py:382 in _call_node_run           │
│                                                                                                  │
│ D:\Program Files\Python\lib\site-packages\kedro\pipeline\node.py:357 in run                      │
│                                                                                                  │
│ D:\Program Files\Python\lib\site-packages\kedro\pipeline\node.py:346 in run                      │
│                                                                                                  │
│ D:\Program Files\Python\lib\site-packages\kedro\pipeline\node.py:377 in _run_with_one_input      │
│                                                                                                  │
│ C:\Users\Administrator\Desktop\PJATK\Semestr_VII\ASI\ASI_Group\asi-kedro\src\asi_kedro\pipelines │
│ \model_evaluation\nodes.py:59 in evaluate_model                                                  │
│                                                                                                  │
│   56 │   fig = plt.figure()                                                                      │
│   57 │   fig.set_figheight(4.5)                                                                  │
│   58 │   fig.set_figwidth(4.5 * 2)                                                               │
│ > 59 │   axes = prediction_summary(predictions_test['y_true'].values, predictions_test['y_pre    │
│   60 │   return fig                                                                              │
│   61                                                                                             │
│                                                                                                  │
│ C:\Users\Administrator\Desktop\PJATK\Semestr_VII\ASI\ASI_Group\asi-kedro\src\asi_kedro\pipelines │
│ \model_evaluation\nodes.py:46 in prediction_summary                                              │
│                                                                                                  │
│   43 │   │   │   "epochs": 10                                                                    │
│   44 │   │   │   }                                                                               │
│   45 │   │   )                                                                                   │
│ > 46 │   │   wandb.log({"confusion_matrix": wandb.plot.confusion_matrix(probs=None,              │
│   47 │   │   │   │   │   │   y_true=labels, preds=predicted_score,                               │
│   48 │   │   │   │   │   │   class_names=['0', '1'])})                                           │
│   49 │   │   plot_metric(axes[1], recall, precision, "Recall", "Precision", "{} AUCPR={:.4f}"    │
│                                                                                                  │
│ D:\Program Files\Python\lib\site-packages\wandb\plot\confusion_matrix.py:78 in confusion_matrix  │
└──────────────────────────────────────────────────────────────────────────────────────────────────┘
KeyError: 0.3311942686297829